Workbook
Name Title1: CashFlow[[#Headers],[Cash Flow]]
Name Title2: Income[[#Headers],[Monthly Income]]
Name Title3: Expenses[[#Headers],[Monthly expenses]]

Sheet Cash flow
C3: Year | E3: 2025
C4: Tot BUDGET
C7: Cash Flow | D7: Actual
C8: Init income | D8: =630+2*35.11+400 -> 1100.22
C9: Total income | D9: ='Yearly income'!D10 -> 6438.79
C10: Total expenses | D10: =Expenses[[#Totals],[Actual]] -> 2980.04
C11: Evaluated Bank Amout | D11: =D8+D9-D10 -> 4558.97
C12: Lost | D12: =SUM(-CashFlow[[#Totals],[Actual]], 4558.97) -> 0

Sheet Yearly income
C10: Yearly INCOME | D10: =SUM(D11:D14) -> 6438.79
C11: PoliMi | D11: =SUM(D23+D34+D45) -> 5016.96
C12: Deddo | D12: =SUM(D24+D35+D46) -> 400
C13: Other income | D13: =SUM(D25+D36+D47) -> 921.83
C14: Cash | D14: =SUM(D26+D37+D48) -> 100
C20: October INCOME
C22: Monthly Income | D22: Actual
C23: PoliMi | D23: =SUMIFS('List Income'!$C$3:$C$100000, 'List Income'!$B$3:$B$100000, 'Yearly income'!$C11, 'List Income'!$A$3:$A$100000, ">=" & DATE(2025, 10, 1), 'List Income'!$A$3:$A$100000, "<" & DATE(2025, 11, 1)) -> 1096.22
C24: Deddo | D24: =SUMIFS('List Income'!$C$3:$C$100000, 'List Income'!$B$3:$B$100000, 'Yearly income'!$C12, 'List Income'!$A$3:$A$100000, ">=" & DATE(2025, 10, 1), 'List Income'!$A$3:$A$100000, "<" & DATE(2025, 11, 1)) -> 0
C25: Other Income | D25: =SUMIFS('List Income'!$C$3:$C$100000, 'List Income'!$B$3:$B$100000, 'Yearly income'!$C13, 'List Income'!$A$3:$A$100000, ">=" & DATE(2025, 10, 1), 'List Income'!$A$3:$A$100000, "<" & DATE(2025, 11, 1)) -> 871.83
C26: Cash | D26: =SUMIFS('List Income'!$C$3:$C$100000, 'List Income'!$B$3:$B$100000, 'Yearly income'!$C14, 'List Income'!$A$3:$A$100000, ">=" & DATE(2025, 10, 1), 'List Income'!$A$3:$A$100000, "<" & DATE(2025, 11, 1)) -> 0
C27: Total Income | D27: =SUBTOTAL(109,Income[Actual]) -> 1968.05
C31: November INCOME
C33: Monthly Income | D33: Actual
C34: PoliMi | D34: =SUMIFS('List Income'!$C$3:$C$100000, 'List Income'!$B$3:$B$100000, 'Yearly income'!$C11, 'List Income'!$A$3:$A$100000, ">=" & DATE(2025, 11, 1), 'List Income'!$A$3:$A$100000, "<" & DATE(2025, 12, 1)) -> 3920.74
C35: Deddo | D35: =SUMIFS('List Income'!$C$3:$C$100000, 'List Income'!$B$3:$B$100000, 'Yearly income'!$C12, 'List Income'!$A$3:$A$100000, ">=" & DATE(2025, 11, 1), 'List Income'!$A$3:$A$100000, "<" & DATE(2025, 12, 1)) -> 400
C36: Other Income | D36: =SUMIFS('List Income'!$C$3:$C$100000, 'List Income'!$B$3:$B$100000, 'Yearly income'!$C13, 'List Income'!$A$3:$A$100000, ">=" & DATE(2025, 11, 1), 'List Income'!$A$3:$A$100000, "<" & DATE(2025, 12, 1)) -> 50
C37: Cash | D37: =SUMIFS('List Income'!$C$3:$C$100000, 'List Income'!$B$3:$B$100000, 'Yearly income'!$C14, 'List Income'!$A$3:$A$100000, ">=" & DATE(2025, 11, 1), 'List Income'!$A$3:$A$100000, "<" & DATE(2025, 12, 1)) -> 100
C38: Total Income | D38: =SUBTOTAL(109,Income18[Actual]) -> 4470.74
C42: December INCOME
C44: Monthly Income | D44: Actual
C45: PoliMi | D45: =SUMIFS('List Income'!$C$3:$C$100000, 'List Income'!$B$3:$B$100000, 'Yearly income'!$C11, 'List Income'!$A$3:$A$100000, ">=" & DATE(2025, 12, 1), 'List Income'!$A$3:$A$100000, "<" & DATE(2026, 1, 1)) -> 0
C46: Deddo | D46: =SUMIFS('List Income'!$C$3:$C$100000, 'List Income'!$B$3:$B$100000, 'Yearly income'!$C12, 'List Income'!$A$3:$A$100000, ">=" & DATE(2025, 12, 1), 'List Income'!$A$3:$A$100000, "<" & DATE(2026, 1, 1)) -> 0
C47: Other Income | D47: =SUMIFS('List Income'!$C$3:$C$100000, 'List Income'!$B$3:$B$100000, 'Yearly income'!$C13, 'List Income'!$A$3:$A$100000, ">=" & DATE(2025, 12, 1), 'List Income'!$A$3:$A$100000, "<" & DATE(2026, 1, 1)) -> 0
C48: Cash | D48: =SUMIFS('List Income'!$C$3:$C$100000, 'List Income'!$B$3:$B$100000, 'Yearly income'!$C14, 'List Income'!$A$3:$A$100000, ">=" & DATE(2025, 12, 1), 'List Income'!$A$3:$A$100000, "<" & DATE(2026, 1, 1)) -> 0
C49: Total Income | D49: =SUBTOTAL(109,Income19[Actual]) -> 0

Sheet Yearly expenses
C3: Yearly EXPENSES
C5: Monthly expenses | D5: Actual
C6: Restaurants | D6: =SUM(D28+D49+D70) -> 0
C7: Groceries | D7: =SUM(D29+D50+D71) -> 201.85
C8: Pre-paid card | D8: =SUM(D30+D51+D72) -> 374.13
C9: Going out | D9: =SUM(D31+D52+D73) -> 214.06
C10: Claudia | D10: =SUM(D32+D53+D74) -> 339.08
C11: Family | D11: =SUM(D33+D54+D75) -> 86.21
C12: Shopping | D12: =SUM(D34+D55+D76) -> 422.89
C13: Transportation | D13: =SUM(D35+D56+D77) -> 303.06
C14: Personal care | D14: =SUM(D36+D57+D78) -> 465.31
C15: Credit cards | D15: =SUM(D37+D58+D79) -> 81.95
C16: Gifts / Charity | D16: =SUM(D38+D59+D80) -> 280
C17: Travel | D17: =SUM(D39+D60+D81) -> 0
... C19: Other | D19: =SUM(D41+D62+D83) -> 211.5
C20: Total expenses | D20: =SUBTOTAL(109,Expenses[Actual]) -> 2980.04
C25: October EXPENSES
C27: Monthly expenses | D27: Actual
C28: Restaurants | D28: =SUMIFS('List Expenses'!$C$3:$C$100002, 'List Expenses'!$B$3:$B$100002, 'Yearly expenses'!$C6, 'List Expenses'!$A$3:$A$100002, ">=" & DATE(2025, 10, 1), 'List Expenses'!$A$3:$A$100002, "<" & DATE(2025, 11, 1)) -> 0
C29: Groceries | D29: =SUMIFS('List Expenses'!$C$3:$C$100002, 'List Expenses'!$B$3:$B$100002, 'Yearly expenses'!$C7, 'List Expenses'!$A$3:$A$100002, ">=" & DATE(2025, 10, 1), 'List Expenses'!$A$3:$A$100002, "<" & DATE(2025, 11, 1)) -> 53.82
C30: Pre-paid card | D30: =SUMIFS('List Expenses'!$C$3:$C$100002, 'List Expenses'!$B$3:$B$100002, 'Yearly expenses'!$C8, 'List Expenses'!$A$3:$A$100002, ">=" & DATE(2025, 10, 1), 'List Expenses'!$A$3:$A$100002, "<" & DATE(2025, 11, 1)) -> 229.13
C31: Going out | D31: =SUMIFS('List Expenses'!$C$3:$C$100002, 'List Expenses'!$B$3:$B$100002, 'Yearly expenses'!$C9, 'List Expenses'!$A$3:$A$100002, ">=" & DATE(2025, 10, 1), 'List Expenses'!$A$3:$A$100002, "<" & DATE(2025, 11, 1)) -> 26.05
C32: Claudia | D32: =SUMIFS('List Expenses'!$C$3:$C$100002, 'List Expenses'!$B$3:$B$100002, 'Yearly expenses'!$C10, 'List Expenses'!$A$3:$A$100002, ">=" & DATE(2025, 10, 1), 'List Expenses'!$A$3:$A$100002, "<" & DATE(2025, 11, 1)) -> 226.39
C33: Family | D33: =SUMIFS('List Expenses'!$C$3:$C$100002, 'List Expenses'!$B$3:$B$100002, 'Yearly expenses'!$C11, 'List Expenses'!$A$3:$A$100002, ">=" & DATE(2025, 10, 1), 'List Expenses'!$A$3:$A$100002, "<" & DATE(2025, 11, 1)) -> 86.21
C34: Shopping | D34: =SUMIFS('List Expenses'!$C$3:$C$100002, 'List Expenses'!$B$3:$B$100002, 'Yearly expenses'!$C12, 'List Expenses'!$A$3:$A$100002, ">=" & DATE(2025, 10, 1), 'List Expenses'!$A$3:$A$100002, "<" & DATE(2025, 11, 1)) -> 422.89
C35: Transportation | D35: =SUMIFS('List Expenses'!$C$3:$C$100002, 'List Expenses'!$B$3:$B$100002, 'Yearly expenses'!$C13, 'List Expenses'!$A$3:$A$100002, ">=" & DATE(2025, 10, 1), 'List Expenses'!$A$3:$A$100002, "<" & DATE(2025, 11, 1)) -> 97.2
C36: Personal care | D36: =SUMIFS('List Expenses'!$C$3:$C$100002, 'List Expenses'!$B$3:$B$100002, 'Yearly expenses'!$C14, 'List Expenses'!$A$3:$A$100002, ">=" & DATE(2025, 10, 1), 'List Expenses'!$A$3:$A$100002, "<" & DATE(2025, 11, 1)) -> 142
C37: Credit cards | D37: =SUMIFS('List Expenses'!$C$3:$C$100002, 'List Expenses'!$B$3:$B$100002, 'Yearly expenses'!$C15, 'List Expenses'!$A$3:$A$100002, ">=" & DATE(2025, 10, 1), 'List Expenses'!$A$3:$A$100002, "<" & DATE(2025, 11, 1)) -> 81.95
C38: Gifts / Charity | D38: =SUMIFS('List Expenses'!$C$3:$C$100002, 'List Expenses'!$B$3:$B$100002, 'Yearly expenses'!$C16, 'List Expenses'!$A$3:$A$100002, ">=" & DATE(2025, 10, 1), 'List Expenses'!$A$3:$A$100002, "<" & DATE(2025, 11, 1)) -> 30
C39: Travel | D39: =SUMIFS('List Expenses'!$C$3:$C$100002, 'List Expenses'!$B$3:$B$100002, 'Yearly expenses'!$C17, 'List Expenses'!$A$3:$A$100002, ">=" & DATE(2025, 10, 1), 'List Expenses'!$A$3:$A$100002, "<" & DATE(2025, 11, 1)) -> 0
... C41: Other | D41: =SUMIFS('List Expenses'!$C$3:$C$100002, 'List Expenses'!$B$3:$B$100002, 'Yearly expenses'!$C19, 'List Expenses'!$A$3:$A$100002, ">=" & DATE(2025, 10, 1), 'List Expenses'!$A$3:$A$100002, "<" & DATE(2025, 11, 1)) -> 101
C42: Total expenses | D42: =SUBTOTAL(109,Expenses2[Actual]) -> 1496.64
C46: November EXPENSES
C48: Monthly expenses | D48: Actual
C49: Restaurants | D49: =SUMIFS('List Expenses'!$C$3:$C$100002, 'List Expenses'!$B$3:$B$100002, 'Yearly expenses'!$C6, 'List Expenses'!$A$3:$A$100002, ">=" & DATE(2025, 11, 1), 'List Expenses'!$A$3:$A$100002, "<" & DATE(2025, 12, 1)) -> 0
C50: Groceries | D50: =SUMIFS('List Expenses'!$C$3:$C$100002, 'List Expenses'!$B$3:$B$100002, 'Yearly expenses'!$C7, 'List Expenses'!$A$3:$A$100002, ">=" & DATE(2025, 11, 1), 'List Expenses'!$A$3:$A$100002, "<" & DATE(2025, 12, 1)) -> 148.03
C51: Pre-paid card | D51: =SUMIFS('List Expenses'!$C$3:$C$100002, 'List Expenses'!$B$3:$B$100002, 'Yearly expenses'!$C8, 'List Expenses'!$A$3:$A$100002, ">=" & DATE(2025, 11, 1), 'List Expenses'!$A$3:$A$100002, "<" & DATE(2025, 12, 1)) -> 145
C52: Going out | D52: =SUMIFS('List Expenses'!$C$3:$C$100002, 'List Expenses'!$B$3:$B$100002, 'Yearly expenses'!$C9, 'List Expenses'!$A$3:$A$100002, ">=" & DATE(2025, 11, 1), 'List Expenses'!$A$3:$A$100002, "<" & DATE(2025, 12, 1)) -> 188.01
C53: Claudia | D53: =SUMIFS('List Expenses'!$C$3:$C$100002, 'List Expenses'!$B$3:$B$100002, 'Yearly expenses'!$C10, 'List Expenses'!$A$3:$A$100002, ">=" & DATE(2025, 11, 1), 'List Expenses'!$A$3:$A$100002, "<" & DATE(2025, 12, 1)) -> 112.69
C54: Family | D54: =SUMIFS('List Expenses'!$C$3:$C$100002, 'List Expenses'!$B$3:$B$100002, 'Yearly expenses'!$C11, 'List Expenses'!$A$3:$A$100002, ">=" & DATE(2025, 11, 1), 'List Expenses'!$A$3:$A$100002, "<" & DATE(2025, 12, 1)) -> 0
...

Sheet List Income
A1: DATE | B1: CATEGORY | C1: AMOUT | D1: DESCRIPTION
A3: 45938 | B3: PoliMi | C3: 1096.22 | D3: First half-payement
A4: 45943 | B4: Other income | C4: 871.83 | D4: Kineton
A5: 45971 | B5: Cash | C5: 100 | D5: Recupero Prelievi Riccardo (Deddo)
A6: 45980 | B6: PoliMi | C6: 2282.4 | D6: First Full payement
A7: 45982 | B7: Deddo | C7: 400 | D7: Reimborso Visite Mediche
A8: 45983 | B8: Other income | C8: 50 | D8: Quota altri regalo Tommaso
A9: 45988 | B9: PoliMi | C9: 1638.34

Sheet List Expenses
A1: DATE | B1: CATEGORY | C1: AMOUNT | D1: DESCRIPTION
A3: 45931 | B3: Shopping | C3: 400 | D3: IKEA per la stanza M
A4: 45940 | B4: Pre-paid card | C4: 82.13
A5: 45941 | B5: Family | C5: =2*35.11 -> 70.22 | D5: Chinese Learning Books for me and Leo
A6: 45943 | B6: Going out | C6: 6
A7: 45944 | B7: Family | C7: 15.99 | D7: New Dad's phone case
A8: 45945 | B8: Credit cards | C8: 81.95
A9: 45946 | B9: Shopping | C9: 22.89 | D9: Cable Lamp (Amazon)
A10: 45946 | B10: Going out | C10: 20.05 | D10: Chinese Glovo
A11: 45948 | B11: Claudia | C11: 29.9 | D11: Yankee Candels
A12: 45948 | B12: Groceries | C12: 53.82 | D12: Amazon Fresh
A13: 45949 | B13: Claudia | C13: 49.93 | D13: Poke Glovo
A14: 45953 | B14: Gifts / Charity | C14: 30 | D14: Regalo Andra Formicola Laurea
A15: 45954 | B15: Personal care | C15: 142 | D15: DelBo Visita
A16: 45954 | B16: Other | C16: 86 | D16: Bonifico Andrea Boldrino Tesi KTH
A17: 45954 | B17: Pre-paid card | C17: =146+1 -> 147
A18: 45954 | B18: Transportation | C18: 2.2 | D18: ATM Milano
A19: 45955 | B19: Claudia | C19: 38.27 | D19: Burger King
A20: 45956 | B20: Claudia | C20: 12.99 | D20: tazza the natale
A21: 45956 | B21: Claudia | C21: 35.4 | D21: Libri Francese
A22: 45958 | B22: Other | C22: 15
A23: 45958 | B23: Claudia | C23: 59.9 | D23: Yankee Calendario avvento
A24: 45960 | B24: Transportation | C24: 95 | D24: Benzina Pieno
A25: 45991 | B25: Transportation | C25: 12 | D25: Parking
A26: 45962 | B26: Transportation | C26: 13.4 | D26: Autostrada
A27: 45962 | B27: Claudia | C27: 18 | D27: Cioccolattini
A28: 45963 | B28: Transportation | C28: 1.5 | D28: Autostrada
A29: 45963 | B29: Transportation | C29: 17.9 | D29: Autostrada
A30: 45963 | B30: Transportation | C30: 2.6 | D30: Autostrada
A31: 45963 | B31: Going out | C31: 57.29 | D31: Sushi Glovo
A32: 45964 | B32: Other | C32: 10 | D32: Microsoft Abbonamento
A33: 45965 | B33: Personal care | C33: 182 | D33: Acufene visita
A34: 45965 | B34: Other | C34: 15
A35: 45965 | B35: Transportation | C35: 2.2 | D35: ATM Milano
A36: 45968 | B36: Other | C36: 15.8
A37: 45970 | B37: Claudia | C37: 31.09
A38: 45971 | B38: Personal care | C38: 84.35 | D38: Prelievi (Riccardo)
A39: 45971 | B39: Personal care | C39: 56.96 | D39: RM con contrasto
A40: 45971 | B40: Gifts / Charity | C40: 100 | D40: Regalo Sofia Compleanno (pagato cash)
A41: 45971 | B41: Groceries | C41: 7.06 | D41: Pasta senza glutine
...
